Workbook

Sheet Variable Information
A1: Variable | B1: Position | C1: Label | D1: WJP variable equivalent | E1: WJP label | F1: Match | G1: Notes | H1: " | I1: renaming
A2: respondentid | B2: 1 | C2: Respondent ID | D2: id | H2: =_xlfn.CONCAT("label var ",A2," ",$H$1,C2,$H$1) -> label var respondentid "Respondent ID"
A3: q11 | B3: 2 | C3: Q11. Gender. Do you identify as: | D3: gend | E3: gend | H3: =_xlfn.CONCAT("label var ",A3," ",$H$1,C3,$H$1) -> label var q11 "Q11. Gender. Do you identify as:" | I3: =_xlfn.CONCAT("rename ",A3," ",E3) -> rename q11 gend
A4: q03 | B4: 3 | C4: Q3. Age | D4: age | E4: age | H4: =_xlfn.CONCAT("label var ",A4," ",$H$1,C4,$H$1) -> label var q03 "Q3. Age" | I4: =_xlfn.CONCAT("rename ",A4," ",E4) -> rename q03 age
A5: q18 | B5: 4 | C5: Q18. Which of the following is the highest level of education or training you have completed? | D5: edu | E5: edu | H5: =_xlfn.CONCAT("label var ",A5," ",$H$1,C5,$H$1) -> label var q18 "Q18. Which of the following is the highest level of education or training you have completed?" | I5: =_xlfn.CONCAT("rename ",A5," ",E5) -> rename q18 edu
A6: education | B6: 5 | C6: Education | D6: edu | E6: edu_2 | G6: Recoded q18 1-4 as 1, 5-11 as 2 | H6: =_xlfn.CONCAT("label var ",A6," ",$H$1,C6,$H$1) -> label var education "Education" | I6: =_xlfn.CONCAT("rename ",A6," ",E6) -> rename education edu_2
A7: q17 | B7: 6 | C7: Q17. Which one of the following best describes your current situation? | D7: emp | E7: emp | H7: =_xlfn.CONCAT("label var ",A7," ",$H$1,C7,$H$1) -> label var q17 "Q17. Which one of the following best describes your current situation?" | I7: =_xlfn.CONCAT("rename ",A7," ",E7) -> rename q17 emp
A8: employment | B8: 7 | C8: Employment | D8: emp | E8: emp_2 | G8: Recoded q17 1=1, 2-9=2 | H8: =_xlfn.CONCAT("label var ",A8," ",$H$1,C8,$H$1) -> label var employment "Employment" | I8: =_xlfn.CONCAT("rename ",A8," ",E8) -> rename employment emp_2
A9: qsocialgrade | B9: 8 | C9: QSocialGrade. Please indicate which occupational group best describes the main earner in your household, or which group fits best. | D9: work | E9: work | H9: =_xlfn.CONCAT("label var ",A9," ",$H$1,C9,$H$1) -> label var qsocialgrade "QSocialGrade. Please indicate which occupational group best describes the main earner in your household, or which group fits best." | I9: =_xlfn.CONCAT("rename ",A9," ",E9) -> rename qsocialgrade work
A10: socialgrade | B10: 9 | C10: Social Grade | D10: work | E10: work_2 | G10: Some sort of grouping of QSocialGrade | H10: =_xlfn.CONCAT("label var ",A10," ",$H$1,C10,$H$1) -> label var socialgrade "Social Grade" | I10: =_xlfn.CONCAT("rename ",A10," ",E10) -> rename socialgrade work_2
A11: county | B11: 10 | C11: County. What is the name of the county where you currently live? | D11: ? | E11: county | H11: =_xlfn.CONCAT("label var ",A11," ",$H$1,C11,$H$1) -> label var county "County. What is the name of the county where you currently live?" | I11: =_xlfn.CONCAT("rename ",A11," ",E11) -> rename county county
A12: region | B12: 11 | C12: Region. | D12: country_code_nuts? | E12: region | H12: =_xlfn.CONCAT("label var ",A12," ",$H$1,C12,$H$1) -> label var region "Region." | I12: =_xlfn.CONCAT("rename ",A12," ",E12) -> rename region region
A13: q23_1_1 | B13: 12 | C13: Q23_1. Are you currently or previously have been in the past two years...? - A tenant | E13: tenant | H13: =_xlfn.CONCAT("label var ",A13," ",$H$1,C13,$H$1) -> label var q23_1_1 "Q23_1. Are you currently or previously have been in the past two years...? - A tenant" | I13: =_xlfn.CONCAT("rename ",A13," ",E13) -> rename q23_1_1 tenant
A14: q23_1_2 | B14: 13 | C14: Q23_1. Are you currently or previously have been in the past two years...? - A landlord | E14: landlord | H14: =_xlfn.CONCAT("label var ",A14," ",$H$1,C14,$H$1) -> label var q23_1_2 "Q23_1. Are you currently or previously have been in the past two years...? - A landlord" | I14: =_xlfn.CONCAT("rename ",A14," ",E14) -> rename q23_1_2 landlord
A15: q23_1_3 | B15: 14 | C15: Q23_1. Are you currently or previously have been in the past two years...? - A home-owner | E15: home_owner | H15: =_xlfn.CONCAT("label var ",A15," ",$H$1,C15,$H$1) -> label var q23_1_3 "Q23_1. Are you currently or previously have been in the past two years...? - A home-owner" | I15: =_xlfn.CONCAT("rename ",A15," ",E15) -> rename q23_1_3 home_owner
A16: q23_2_01_1 | B16: 15 | C16: Q23_2_1_1. Issues experienced - Including issues with buying or selling property and disputes over title or ownership boundary locations and rights of way and Land Registry matters | D16: AJP | E16: AJP_A1 | H16: =_xlfn.CONCAT("label var ",A16," ",$H$1,C16,$H$1) -> label var q23_2_01_1 "Q23_2_1_1. Issues experienced - Including issues with buying or selling property and disputes over title or ownership boundary locations and rights of way and Land Registry matters"
A17: q23_2_02_1 | B17: 16 | C17: Q23_2_2_1. Issues experienced - Disputes about maintenance including of boundaries trees gardens | D17: AJP | E17: AJP_B1 | H17: =_xlfn.CONCAT("label var ",A17," ",$H$1,C17,$H$1) -> label var q23_2_02_1 "Q23_2_2_1. Issues experienced - Disputes about maintenance including of boundaries trees gardens"
A18: q23_2_02_2 | B18: 17 | C18: Q23_2_2_2. Issues experienced - Problems or disputes to do with noise animals or unpleasant behaviour | D18: AJP | E18: AJP_B2 | H18: =_xlfn.CONCAT("label var ",A18," ",$H$1,C18,$H$1) -> label var q23_2_02_2 "Q23_2_2_2. Issues experienced - Problems or disputes to do with noise animals or unpleasant behaviour"
A19: q23_2_02_3 | B19: 18 | C19: Q23_2_2_3. Issues experienced - Other disputes with neighbours such as issues with parking | D19: AJP | E19: AJP_B3 | H19: =_xlfn.CONCAT("label var ",A19," ",$H$1,C19,$H$1) -> label var q23_2_02_3 "Q23_2_2_3. Issues experienced - Other disputes with neighbours such as issues with parking"
A20: q23_2_03_1 | B20: 19 | C20: Q23_2_3_1. Issues experienced - Problems or disputes with your landlord over your rent or return of deposit | D20: AJP | E20: AJP_C1 | H20: =_xlfn.CONCAT("label var ",A20," ",$H$1,C20,$H$1) -> label var q23_2_03_1 "Q23_2_3_1. Issues experienced - Problems or disputes with your landlord over your rent or return of deposit"
A21: q23_2_03_2 | B21: 20 | C21: Q23_2_3_2. Issues experienced - Problem with your landlord about the condition of your accommodation including damage/repairs | D21: AJP | E21: AJP_C2 | H21: =_xlfn.CONCAT("label var ",A21," ",$H$1,C21,$H$1) -> label var q23_2_03_2 "Q23_2_3_2. Issues experienced - Problem with your landlord about the condition of your accommodation including damage/repairs"
A22: q23_2_03_3 | B22: 21 | C22: Q23_2_3_3. Issues experienced - Eviction or threats of eviction or other harassment by a landlord | D22: AJP | E22: AJP_C3 | H22: =_xlfn.CONCAT("label var ",A22," ",$H$1,C22,$H$1) -> label var q23_2_03_3 "Q23_2_3_3. Issues experienced - Eviction or threats of eviction or other harassment by a landlord"
A23: q23_2_04_1 | B23: 22 | C23: Q23_2_4_1. Issues experienced - Issues with a tenant such as delayed/no payment of rent or dispute over a deposit | D23: AJP | E23: AJP_D1 | H23: =_xlfn.CONCAT("label var ",A23," ",$H$1,C23,$H$1) -> label var q23_2_04_1 "Q23_2_4_1. Issues experienced - Issues with a tenant such as delayed/no payment of rent or dispute over a deposit"
A24: q23_2_04_2 | B24: 23 | C24: Q23_2_4_2. Issues experienced - Property-related issues such as damage by tenants or access to property | D24: AJP | E24: AJP_D2 | H24: =_xlfn.CONCAT("label var ",A24," ",$H$1,C24,$H$1) -> label var q23_2_04_2 "Q23_2_4_2. Issues experienced - Property-related issues such as damage by tenants or access to property"
A25: q23_2_04_3 | B25: 24 | C25: Q23_2_4_3. Issues experienced - Issues with tenants such as evictions or complaints | D25: AJP | E25: AJP_D3 | H25: =_xlfn.CONCAT("label var ",A25," ",$H$1,C25,$H$1) -> label var q23_2_04_3 "Q23_2_4_3. Issues experienced - Issues with tenants such as evictions or complaints"
A26: q23_2_05_1 | B26: 25 | C26: Q23_2_5_1. Issues experienced - Building/planning related disputes | D26: AJP | E26: AJP_E1 | H26: =_xlfn.CONCAT("label var ",A26," ",$H$1,C26,$H$1) -> label var q23_2_05_1 "Q23_2_5_1. Issues experienced - Building/planning related disputes"
A27: q23_2_05_2 | B27: 26 | C27: Q23_2_5_2. Issues experienced - Issues with builders/tradespeople about the quality of construction or repairs or disputes about costs | D27: AJP | E27: AJP_E2 | H27: =_xlfn.CONCAT("label var ",A27," ",$H$1,C27,$H$1) -> label var q23_2_05_2 "Q23_2_5_2. Issues experienced - Issues with builders/tradespeople about the quality of construction or repairs or disputes about costs"
... A71: q23_2_14_4 | B71: 70 | C71: Q23_2_14_4. Issues experienced - Other employment-related disputes | D71: AJP | E71: AJP_N4 | H71: =_xlfn.CONCAT("label var ",A71," ",$H$1,C71,$H$1) -> label var q23_2_14_4 "Q23_2_14_4. Issues experienced - Other employment-related disputes"
A72: q23_3_01_1 | B72: 71 | C72: Q23_3_1_1. Frequency experienced - Including issues with buying or selling property and disputes over title or ownership boundary locations and rights of way and Land Registry matters | E72: AJP_A1_freq | H72: =_xlfn.CONCAT("label var ",A72," ",$H$1,C72,$H$1) -> label var q23_3_01_1 "Q23_3_1_1. Frequency experienced - Including issues with buying or selling property and disputes over title or ownership boundary locations and rights of way and Land Registry matters"
A73: q23_3_02_1 | B73: 72 | C73: Q23_3_2_1. Frequency experienced - Disputes about maintenance including of boundaries trees gardens | E73: AJP_B1_freq | H73: =_xlfn.CONCAT("label var ",A73," ",$H$1,C73,$H$1) -> label var q23_3_02_1 "Q23_3_2_1. Frequency experienced - Disputes about maintenance including of boundaries trees gardens"
A74: q23_3_02_2 | B74: 73 | C74: Q23_3_2_2. Frequency experienced - Problems or disputes to do with noise animals or unpleasant behaviour | E74: AJP_B2_freq | H74: =_xlfn.CONCAT("label var ",A74," ",$H$1,C74,$H$1) -> label var q23_3_02_2 "Q23_3_2_2. Frequency experienced - Problems or disputes to do with noise animals or unpleasant behaviour"
A75: q23_3_02_3 | B75: 74 | C75: Q23_3_2_3. Frequency experienced - Other disputes with neighbours such as issues with parking | E75: AJP_B3_freq | H75: =_xlfn.CONCAT("label var ",A75," ",$H$1,C75,$H$1) -> label var q23_3_02_3 "Q23_3_2_3. Frequency experienced - Other disputes with neighbours such as issues with parking"
A76: q23_3_03_1 | B76: 75 | C76: Q23_3_3_1. Frequency experienced - Problems or disputes with your landlord over your rent or return of deposit | E76: AJP_C1_freq | H76: =_xlfn.CONCAT("label var ",A76," ",$H$1,C76,$H$1) -> label var q23_3_03_1 "Q23_3_3_1. Frequency experienced - Problems or disputes with your landlord over your rent or return of deposit"
A77: q23_3_03_2 | B77: 76 | C77: Q23_3_3_2. Frequency experienced - Problem with your landlord about the condition of your accommodation including damage/repairs | E77: AJP_C2_freq | H77: =_xlfn.CONCAT("label var ",A77," ",$H$1,C77,$H$1) -> label var q23_3_03_2 "Q23_3_3_2. Frequency experienced - Problem with your landlord about the condition of your accommodation including damage/repairs"
A78: q23_3_03_3 | B78: 77 | C78: Q23_3_3_3. Frequency experienced - Eviction or threats of eviction or other harassment by a landlord | E78: AJP_C3_freq | H78: =_xlfn.CONCAT("label var ",A78," ",$H$1,C78,$H$1) -> label var q23_3_03_3 "Q23_3_3_3. Frequency experienced - Eviction or threats of eviction or other harassment by a landlord"
A79: q23_3_04_1 | B79: 78 | C79: Q23_3_4_1. Frequency experienced - Issues with a tenant such as delayed/no payment of rent or dispute over a deposit | E79: AJP_D1_freq | H79: =_xlfn.CONCAT("label var ",A79," ",$H$1,C79,$H$1) -> label var q23_3_04_1 "Q23_3_4_1. Frequency experienced - Issues with a tenant such as delayed/no payment of rent or dispute over a deposit"
A80: q23_3_04_2 | B80: 79 | C80: Q23_3_4_2. Frequency experienced - Property-related issues such as damage by tenants or access to property | E80: AJP_D2_freq | H80: =_xlfn.CONCAT("label var ",A80," ",$H$1,C80,$H$1) -> label var q23_3_04_2 "Q23_3_4_2. Frequency experienced - Property-related issues such as damage by tenants or access to property"
A81: q23_3_04_3 | B81: 80 | C81: Q23_3_4_3. Frequency experienced - Issues with tenants such as evictions or complaints | E81: AJP_D3_freq | H81: =_xlfn.CONCAT("label var ",A81," ",$H$1,C81,$H$1) -> label var q23_3_04_3 "Q23_3_4_3. Frequency experienced - Issues with tenants such as evictions or complaints"
A82: q23_3_05_1 | B82: 81 | C82: Q23_3_5_1. Frequency experienced - Building/planning related disputes | E82: AJP_E1_freq | H82: =_xlfn.CONCAT("label var ",A82," ",$H$1,C82,$H$1) -> label var q23_3_05_1 "Q23_3_5_1. Frequency experienced - Building/planning related disputes"
A83: q23_3_05_2 | B83: 82 | C83: Q23_3_5_2. Frequency experienced - Issues with builders/tradespeople about the quality of construction or repairs or disputes about costs | E83: AJP_E2_freq | H83: =_xlfn.CONCAT("label var ",A83," ",$H$1,C83,$H$1) -> label var q23_3_05_2 "Q23_3_5_2. Frequency experienced - Issues with builders/tradespeople about the quality of construction or repairs or disputes about costs"
...

Sheet Variable Values
A1: WJP label | B1: Question label | C1: Value | E1: Label
A2: =VLOOKUP($C2,'Variable Information'!$A$2:$E$480,5,FALSE) -> gend | B2: =VLOOKUP($C2,'Variable Information'!$A$1:$C$480,3,FALSE) -> Q11. Gender. Do you identify as: | C2: q11 | D2: 1 | E2: Male
A3: =VLOOKUP($C3,'Variable Information'!$A$2:$E$480,5,FALSE) -> #N/A | B3: =VLOOKUP($C3,'Variable Information'!$A$1:$C$480,3,FALSE) -> #N/A | D3: 2 | E3: Female
A4: =VLOOKUP($C4,'Variable Information'!$A$2:$E$480,5,FALSE) -> #N/A | B4: =VLOOKUP($C4,'Variable Information'!$A$1:$C$480,3,FALSE) -> #N/A | D4: 3 | E4: Other/Prefer not to say
A5: =VLOOKUP($C5,'Variable Information'!$A$2:$E$480,5,FALSE) -> age | B5: =VLOOKUP($C5,'Variable Information'!$A$1:$C$480,3,FALSE) -> Q3. Age | C5: q03 | D5: 1 | E5: 18-24
A6: =VLOOKUP($C6,'Variable Information'!$A$2:$E$480,5,FALSE) -> #N/A | B6: =VLOOKUP($C6,'Variable Information'!$A$1:$C$480,3,FALSE) -> #N/A | D6: 2 | E6: 25-34
A7: =VLOOKUP($C7,'Variable Information'!$A$2:$E$480,5,FALSE) -> #N/A | B7: =VLOOKUP($C7,'Variable Information'!$A$1:$C$480,3,FALSE) -> #N/A | D7: 3 | E7: 35-44
A8: =VLOOKUP($C8,'Variable Information'!$A$2:$E$480,5,FALSE) -> #N/A | B8: =VLOOKUP($C8,'Variable Information'!$A$1:$C$480,3,FALSE) -> #N/A | D8: 4 | E8: 45-54
A9: =VLOOKUP($C9,'Variable Information'!$A$2:$E$480,5,FALSE) -> #N/A | B9: =VLOOKUP($C9,'Variable Information'!$A$1:$C$480,3,FALSE) -> #N/A | D9: 5 | E9: 55-64
A10: =VLOOKUP($C10,'Variable Information'!$A$2:$E$480,5,FALSE) -> #N/A | B10: =VLOOKUP($C10,'Variable Information'!$A$1:$C$480,3,FALSE) -> #N/A | D10: 6 | E10: 65-74
A11: =VLOOKUP($C11,'Variable Information'!$A$2:$E$480,5,FALSE) -> #N/A | B11: =VLOOKUP($C11,'Variable Information'!$A$1:$C$480,3,FALSE) -> #N/A | D11: 7 | E11: 75+
A12: =VLOOKUP($C12,'Variable Information'!$A$2:$E$480,5,FALSE) -> edu | B12: =VLOOKUP($C12,'Variable Information'!$A$1:$C$480,3,FALSE) -> Q18. Which of the following is the highest level of education or training you have completed? | C12: q18 | D12: 1 | E12: No formal education/training
A13: =VLOOKUP($C13,'Variable Information'!$A$2:$E$480,5,FALSE) -> #N/A | B13: =VLOOKUP($C13,'Variable Information'!$A$1:$C$480,3,FALSE) -> #N/A | D13: 2 | E13: Primary education
A14: =VLOOKUP($C14,'Variable Information'!$A$2:$E$480,5,FALSE) -> #N/A | B14: =VLOOKUP($C14,'Variable Information'!$A$1:$C$480,3,FALSE) -> #N/A | D14: 3 | E14: Lower secondary - Junior/Inter/Group Certificate
A15: =VLOOKUP($C15,'Variable Information'!$A$2:$E$480,5,FALSE) -> #N/A | B15: =VLOOKUP($C15,'Variable Information'!$A$1:$C$480,3,FALSE) -> #N/A | D15: 4 | E15: Upper Secondary - Leaving Certificate
A16: =VLOOKUP($C16,'Variable Information'!$A$2:$E$480,5,FALSE) -> #N/A | B16: =VLOOKUP($C16,'Variable Information'!$A$1:$C$480,3,FALSE) -> #N/A | D16: 5 | E16: Technical or Vocational
A17: =VLOOKUP($C17,'Variable Information'!$A$2:$E$480,5,FALSE) -> #N/A | B17: =VLOOKUP($C17,'Variable Information'!$A$1:$C$480,3,FALSE) -> #N/A | D17: 6 | E17: Advanced Certificate/Completed Apprenticeship
A18: =VLOOKUP($C18,'Variable Information'!$A$2:$E$480,5,FALSE) -> #N/A | B18: =VLOOKUP($C18,'Variable Information'!$A$1:$C$480,3,FALSE) -> #N/A | D18: 7 | E18: Higher Certificate
A19: =VLOOKUP($C19,'Variable Information'!$A$2:$E$480,5,FALSE) -> #N/A | B19: =VLOOKUP($C19,'Variable Information'!$A$1:$C$480,3,FALSE) -> #N/A | D19: 8 | E19: Ordinary Bachelor's degree or National Diploma
A20: =VLOOKUP($C20,'Variable Information'!$A$2:$E$480,5,FALSE) -> #N/A | B20: =VLOOKUP($C20,'Variable Information'!$A$1:$C$480,3,FALSE) -> #N/A | D20: 9 | E20: Honours Bachelor's degree/Professional Qualification or both
A21: =VLOOKUP($C21,'Variable Information'!$A$2:$E$480,5,FALSE) -> #N/A | B21: =VLOOKUP($C21,'Variable Information'!$A$1:$C$480,3,FALSE) -> #N/A | D21: 10 | E21: Postgraduate Diploma or Master's Degree
A22: =VLOOKUP($C22,'Variable Information'!$A$2:$E$480,5,FALSE) -> #N/A | B22: =VLOOKUP($C22,'Variable Information'!$A$1:$C$480,3,FALSE) -> #N/A | D22: 11 | E22: Doctorate (PhD) or higher
A23: =VLOOKUP($C23,'Variable Information'!$A$2:$E$480,5,FALSE) -> edu_2 | B23: =VLOOKUP($C23,'Variable Information'!$A$1:$C$480,3,FALSE) -> Education | C23: education | D23: 1 | E23: Lower education
A24: =VLOOKUP($C24,'Variable Information'!$A$2:$E$480,5,FALSE) -> #N/A | B24: =VLOOKUP($C24,'Variable Information'!$A$1:$C$480,3,FALSE) -> #N/A | D24: 2 | E24: Higher education
A25: =VLOOKUP($C25,'Variable Information'!$A$2:$E$480,5,FALSE) -> emp | B25: =VLOOKUP($C25,'Variable Information'!$A$1:$C$480,3,FALSE) -> Q17. Which one of the following best describes your current situation? | C25: q17 | D25: 1 | E25: Employed
A26: =VLOOKUP($C26,'Variable Information'!$A$2:$E$480,5,FALSE) -> #N/A | B26: =VLOOKUP($C26,'Variable Information'!$A$1:$C$480,3,FALSE) -> #N/A | D26: 2 | E26: Self-employed
A27: =VLOOKUP($C27,'Variable Information'!$A$2:$E$480,5,FALSE) -> #N/A | B27: =VLOOKUP($C27,'Variable Information'!$A$1:$C$480,3,FALSE) -> #N/A | D27: 3 | E27: Unemployed and looking for work
A28: =VLOOKUP($C28,'Variable Information'!$A$2:$E$480,5,FALSE) -> #N/A | B28: =VLOOKUP($C28,'Variable Information'!$A$1:$C$480,3,FALSE) -> #N/A | D28: 4 | E28: Retired
A29: =VLOOKUP($C29,'Variable Information'!$A$2:$E$480,5,FALSE) -> #N/A | B29: =VLOOKUP($C29,'Variable Information'!$A$1:$C$480,3,FALSE) -> #N/A | D29: 5 | E29: Unable to work due to long standing health problems
A30: =VLOOKUP($C30,'Variable Information'!$A$2:$E$480,5,FALSE) -> #N/A | B30: =VLOOKUP($C30,'Variable Information'!$A$1:$C$480,3,FALSE) -> #N/A | D30: 6 | E30: Full time Student/Pupil
A31: =VLOOKUP($C31,'Variable Information'!$A$2:$E$480,5,FALSE) -> #N/A | B31: =VLOOKUP($C31,'Variable Information'!$A$1:$C$480,3,FALSE) -> #N/A | D31: 7 | E31: Looking after home/family
A32: =VLOOKUP($C32,'Variable Information'!$A$2:$E$480,5,FALSE) -> #N/A | B32: =VLOOKUP($C32,'Variable Information'!$A$1:$C$480,3,FALSE) -> #N/A | D32: 8 | E32: Not working and not looking for work
A33: =VLOOKUP($C33,'Variable Information'!$A$2:$E$480,5,FALSE) -> #N/A | B33: =VLOOKUP($C33,'Variable Information'!$A$1:$C$480,3,FALSE) -> #N/A | D33: 9 | E33: Other, please specify:
A34: =VLOOKUP($C34,'Variable Information'!$A$2:$E$480,5,FALSE) -> emp_2 | B34: =VLOOKUP($C34,'Variable Information'!$A$1:$C$480,3,FALSE) -> Employment | C34: employment | D34: 1 | E34: Full-time
A35: =VLOOKUP($C35,'Variable Information'!$A$2:$E$480,5,FALSE) -> #N/A | B35: =VLOOKUP($C35,'Variable Information'!$A$1:$C$480,3,FALSE) -> #N/A | D35: 2 | E35: Others
A36: =VLOOKUP($C36,'Variable Information'!$A$2:$E$480,5,FALSE) -> work | B36: =VLOOKUP($C36,'Variable Information'!$A$1:$C$480,3,FALSE) -> QSocialGrade. Please indicate which occupational group best describes the main earner in your household, or which group fits best. | C36: qsocialgrade | D36: 1 | E36: Higher managerial/ professional/ administrative (e.g. Established doctor, Solicitor, Board Director<br/>in a large organ
A37: =VLOOKUP($C37,'Variable Information'!$A$2:$E$480,5,FALSE) -> #N/A | B37: =VLOOKUP($C37,'Variable Information'!$A$1:$C$480,3,FALSE) -> #N/A | D37: 2 | E37: Intermediate managerial/ professional/ administrative (e.g. Newly qualified (under 3 years) doctor,<br/>Solicitor, Board
A38: =VLOOKUP($C38,'Variable Information'!$A$2:$E$480,5,FALSE) -> #N/A | B38: =VLOOKUP($C38,'Variable Information'!$A$1:$C$480,3,FALSE) -> #N/A | D38: 3 | E38: Supervisory or clerical/ junior managerial/ professional/ administrative (e.g. Office worker,<br/>Student Doctor, Forema
A39: =VLOOKUP($C39,'Variable Information'!$A$2:$E$480,5,FALSE) -> #N/A | B39: =VLOOKUP($C39,'Variable Information'!$A$1:$C$480,3,FALSE) -> #N/A | D39: 4 | E39: Student
A40: =VLOOKUP($C40,'Variable Information'!$A$2:$E$480,5,FALSE) -> #N/A | B40: =VLOOKUP($C40,'Variable Information'!$A$1:$C$480,3,FALSE) -> #N/A | D40: 5 | E40: Skilled manual worker (e.g. Skilled Bricklayer, Carpenter, Plumber, Painter, Bus/ Ambulance Driver,<br/>HGV driver, AA p
...
